"""
Tests for the Database class in the American Law Search application.

This module contains unittest tests for the Database class defined in
api_/database/database.py, focusing on testing each method for basic functionality.
"""

import unittest
from unittest.mock import MagicMock, patch, PropertyMock, mock_open


import time
import os
from queue import Queue
from typing import Any, Dict



# Import the class to be tested
from app.api_.database.database import Database, try_except
from app.configs import configs, Configs


class TestTryExceptDecorator(unittest.TestCase):
    """Tests for the try_except decorator."""
    
    def test_try_except_no_exception(self):
        """Test that try_except returns the function result when no exception occurs."""
        @try_except(raise_=True)
        def test_func():
            return "success"
            
        result = test_func()
        self.assertEqual(result, "success")
    
    @patch('api_.database.database.logger')
    def test_try_except_with_exception(self, mock_logger):
        """Test that try_except catches exceptions."""
        @try_except(msg="Test exception",raise_=False)
        def test_func():
            raise ValueError("Test error")
            
        # The function should not raise an exception
        result = test_func()
        self.assertIsNone(result)
        mock_logger.exception.assert_called_once()
    
    def test_try_except_with_reraise(self):
        """Test that try_except re-raises exceptions when raise_ is True."""
        @try_except(msg="Test exception", raise_=True)
        def test_func():
            raise ValueError("Test error")
            
        # The function should raise an exception
        with self.assertRaises(ValueError):
            test_func()
    
    @patch('api_.database.database.logger')
    def test_try_except_specific_exception(self, mock_logger):
        """Test that try_except only catches the specified exception type."""
        @try_except(exception_type=ValueError, msg="Test exception", raise_=False)
        def test_func(exc_type):
            raise exc_type("Test error")
            
        # Should catch ValueError
        result = test_func(ValueError)
        self.assertIsNone(result)
        mock_logger.exception.assert_called_once()
        
        # Reset the mock
        mock_logger.reset_mock()
        
        # Should not catch TypeError
        with self.assertRaises(TypeError):
            test_func(TypeError)

class TestTryExceptDecoratorEdgeCases(unittest.TestCase):
    """Edge cases for the try_except decorator."""

    def test_try_except_preserves_function_metadata(self):
        """Test that try_except preserves function name, docstring, etc."""
        @try_except(raise_=False)
        def test_func():
            """Test docstring."""
            pass
                
        self.assertEqual(test_func.__name__, "test_func")
        self.assertEqual(test_func.__doc__, "Test docstring.")
        
    def test_try_except_with_instance_method(self):
        """Test that try_except works with instance methods."""
        class TestClass:
            @try_except(raise_=False)
            def test_method(self):
                raise ValueError("Test error")
        
        instance = TestClass()
        result = instance.test_method()  # Should not raise
        self.assertIsNone(result)
        
    def test_try_except_with_class_method(self):
        """Test that try_except works with class methods."""
        class TestClass:
            @classmethod
            @try_except(raise_=False)
            def test_method(cls):
                raise ValueError("Test error")
        
        result = TestClass.test_method()  # Should not raise
        self.assertIsNone(result)
        
    def test_try_except_custom_return_value(self):
        """Test try_except with a custom return value for exceptions."""
        @try_except(raise_=False, default_return="error occurred")
        def test_func():
            raise ValueError("Test error")
                
        result = test_func()
        self.assertEqual(result, "error occurred")
        
    @patch('api_.database.database.logger', side_effect=Exception("Logger error"))
    def test_try_except_logger_error(self, mock_logger):
        """Test behavior when logger itself raises an exception."""
        @try_except(raise_=False)
        def test_func():
            raise ValueError("Test error")
                
        # Should not propagate the logger exception
        result = test_func()
        self.assertIsNone(result)
        
    def test_try_except_multiple_exception_types(self):
        """Test handling multiple exception types."""
        @try_except(exception_type=(ValueError, TypeError), raise_=False)
        def test_func(exc_type):
            raise exc_type("Test error")
                
        # Should catch both ValueError and TypeError
        result1 = test_func(ValueError)
        self.assertIsNone(result1)
        
        result2 = test_func(TypeError)
        self.assertIsNone(result2)
        
        # Should not catch KeyError
        with self.assertRaises(KeyError):
            test_func(KeyError)

    def test_try_except_with_kwargs(self):
        """Test that try_except works with functions that take keyword arguments."""
        @try_except(raise_=False)
        def test_func(a, b=2):
            return a + b
            
        result = test_func(1, b=3)
        self.assertEqual(result, 4)

    def test_try_except_with_wildcard(self):
        """Test that try_except works with functions that take both args and kwargs."""
        @try_except(raise_=False)
        def test_func(a, b=2, *args, **kwargs):
            return a + b + sum(args) + sum(kwargs.values())
            
        result = test_func(1, 3, 4, 5, x=6, y=7)
        self.assertEqual(result, 26)

    def test_try_except_stacking(self):
        """
        Test that try_except can be stacked on top of each other.
        ie
        This:
            @try_except(raise_=False)
            @try_except(raise_=False)
            def func(*args, **kwargs):
                return *args, **kwargs

        Is equivalent to:
            try:
                return func(*args, **kwargs)
            except ValueError as e:
                logger.exception("ValueError occurred")
                raise e
            except Exception as e:
                logger.exception("Unexpected error occurred")
                return None
        """
        # Test with no exception - both decorators should pass through
        @try_except(raise_=False)
        @try_except(raise_=False)
        def test_success(*args, **kwargs):
            return sum(args) + sum(kwargs.values())

        result = test_success(1, 2, a=3, b=4)
        self.assertEqual(result, 10)

        # Test with exception - should be caught by the outermost decorator
        @try_except(raise_=False, default_return="outer")
        @try_except(raise_=True, default_return="inner")
        def test_error():
            raise ValueError("Test error")

        # Inner decorator re-raises, outer catches and returns default
        result = test_error()
        self.assertEqual(result, "outer")

        # Test with different exception types
        @try_except(exception_type=TypeError, raise_=False, default_return="outer")
        @try_except(exception_type=ValueError, raise_=False, default_return="inner")
        def test_mixed_error(exc_type):
            raise exc_type("Test error")

        # ValueError caught by inner decorator
        result = test_mixed_error(ValueError)
        self.assertEqual(result, "inner")

        # TypeError caught by outer decorator
        result = test_mixed_error(TypeError)
        self.assertEqual(result, "outer")

        # KeyError not caught by either
        with self.assertRaises(KeyError):
            test_mixed_error(KeyError)

        # Test with different exception types that raise and some that don't
        @try_except(exception_type=TypeError, raise_=True, default_return="outer")
        @try_except(exception_type=ValueError, raise_=False, default_return="inner")
        def test_mixed_error(exc_type):
            raise exc_type("Test error")

        # ValueError caught by inner decorator
        result = test_mixed_error(ValueError)
        self.assertEqual(result, "inner")

        # TypeError raised by outer decorator
        with self.assertRaises(TypeError):
            test_mixed_error(TypeError)

        # KeyError not caught by either
        with self.assertRaises(KeyError):
            test_mixed_error(KeyError)


class TestAsyncTryExceptDecorator(unittest.IsolatedAsyncioTestCase):
    """Tests for the async try_except decorator."""

    async def asyncSetUp(self):
        pass

    async def test_try_except_no_exception(self):
        """Test that try_except returns the function result when no exception occurs."""
        @try_except(raise_=True)
        async def test_func():
            return "success"
            
        result = await test_func()
        self.assertEqual(result, "success")

    @patch('api_.database.database.logger')
    async def test_try_except_with_exception(self, mock_logger):
        """Test that try_except catches exceptions."""
        @try_except(msg="Test exception",raise_=False)
        async def test_func():
            raise ValueError("Test error")
            
        # The function should not raise an exception
        result = await test_func()
        self.assertIsNone(result)
        mock_logger.exception.assert_called_once()

    async def test_try_except_with_reraise(self):
        """Test that try_except re-raises exceptions when raise_ is True."""
        @try_except(msg="Test exception", raise_=True)
        async def test_func():
            raise ValueError("Test error")
            
        # The function should raise an exception
        with self.assertRaises(ValueError):
            await test_func()

    @patch('api_.database.database.logger')
    async def test_try_except_specific_exception(self, mock_logger):
        """Test that try_except only catches the specified exception type."""
        @try_except(exception_type=ValueError, msg="Test exception", raise_=False)
        async def test_func(exc_type):
            raise exc_type("Test error")
            
        # Should catch ValueError
        result = await test_func(ValueError)
        self.assertIsNone(result)
        mock_logger.exception.assert_called_once()

        # Reset the mock
        mock_logger.reset_mock()

        # Should not catch TypeError
        with self.assertRaises(TypeError):
            await test_func(TypeError)